<?xml version="1.4"?>
<robot name="quadrupedal_robot">

	<material name="blue">
		<color rgba="0 0 .8 1" />
	</material>

	<material name="red">
		<color rgba=".8 0 0 1" />
	</material>

	<material name="white">
		<color rgba="1 1 1 1" />
	</material>

	<link name="dummy" />

	<link name="base_link">
		<visual>
			<origin xyz="0 0 0" rpy="0 0 0"/>
			<geometry>				
				<box size="1 .4 .2" />
			</geometry>
			<material name="white" />
		</visual>

		<collision>
			<origin xyz="0 0 0" rpy="0 0 0"/>
			<geometry>				
				<box size="1 .4 .2" />
			</geometry>
		</collision>

		<inertial>
			<mass value="15" />

			<inertia ixx="20.3125" ixy="0" ixz="0" iyy="22.8125" iyz="0" izz="3.125" />
		</inertial>
	</link>

	<link name="left_front_shoulder" >
		<visual>
			<origin xyz="-.05 0 0" rpy="0 1.57 0"/>
			<geometry>				
				<cylinder radius=".05" length=".1" />
			</geometry>
			<material name="blue" />
		</visual>

		<collision>
			<origin xyz="-.05 0 0" rpy="0 1.57 0"/>
			<geometry>				
				<cylinder radius=".05" length=".1" />
			</geometry>
		</collision>

		<inertial>
			<mass value=".5" />

			<inertia ixx=".001354" ixy="0" ixz="0" iyy=".0025" iyz="0" izz=".001354" />
		</inertial>
	</link>

	<link name="right_front_shoulder">
		<visual>
			<origin xyz="-.05 0 0" rpy="0 1.57 0"/>
			<geometry>				
				<cylinder radius=".05" length=".1" />
			</geometry>
			<material name="blue" />
		</visual>

		<collision>
			<origin xyz="-.05 0 0" rpy="0 1.57 0"/>
			<geometry>				
				<cylinder radius=".05" length=".1" />
			</geometry>
			<material name="blue" />
		</collision>

		<inertial>
			<mass value=".5" />

			<inertia ixx=".001354" ixy="0" ixz="0" iyy=".0025" iyz="0" izz=".001354" />
		</inertial>
	</link>

	<link name="left_back_shoulder">
		<visual>
			<origin xyz="-.05 0 0" rpy="0 1.57 0"/>
			<geometry>				
				<cylinder radius=".05" length=".1" />
			</geometry>
			<material name="blue" />
		</visual>

		<collision>
			<origin xyz="-.05 0 0" rpy="0 1.57 0"/>
			<geometry>				
				<cylinder radius=".05" length=".1" />
			</geometry>
		</collision>

		<inertial>
			<mass value=".5" />

			<inertia ixx=".001354" ixy="0" ixz="0" iyy=".0025" iyz="0" izz=".001354" />
		</inertial>
	</link>

	<link name="right_back_shoulder">
		<visual>
			<origin xyz="-.05 0 0" rpy="0 1.57 0"/>
			<geometry>				
				<cylinder radius=".05" length=".1" />
			</geometry>
			<material name="blue" />
		</visual>

		<collision>
			<origin xyz="-.05 0 0" rpy="0 1.57 0"/>
			<geometry>				
				<cylinder radius=".05" length=".1" />
			</geometry>
		</collision>

		<inertial>
			<mass value=".5" />

			<inertia ixx=".001354" ixy="0" ixz="0" iyy=".0025" iyz="0" izz=".001354" />
		</inertial>
	</link>

	<link name="left_front_leg" >
		<visual>
			<origin xyz="0.2 0 0" rpy="0 1.57 0"/>
			<geometry>				
				<cylinder radius=".05" length="0.4" />
			</geometry>
			<material name="red" />
		</visual>

		<collision>
			<origin xyz="0.2 0 0" rpy="0 1.57 0"/>
			<geometry>				
				<cylinder radius=".05" length="0.4" />
			</geometry>
		</collision>

		<inertial>
			<mass value="3" />

			<inertia ixx="4" ixy="0" ixz="0" iyy="4" iyz="0" izz="0" />
		</inertial>
	</link>

	<link name="right_front_leg" >
		<visual>
			<origin xyz="0.2 0 0" rpy="0 1.57 0"/>
			<geometry>				
				<cylinder radius=".05" length="0.4" />
			</geometry>
			<material name="red" />
		</visual>

		<collision>
			<origin xyz="0.2 0 0" rpy="0 1.57 0"/>
			<geometry>				
				<cylinder radius=".05" length="0.4" />
			</geometry>
		</collision>

		<inertial>
			<mass value="3" />

			<inertia ixx="4" ixy="0" ixz="0" iyy="4" iyz="0" izz="0" />
		</inertial>
	</link>

	<link name="left_back_leg" >
		<visual>
			<origin xyz="0.2 0 0" rpy="0 1.57 0"/>
			<geometry>				
				<cylinder radius=".05" length="0.4" />
			</geometry>
			<material name="red" />
		</visual>

		<collision>
			<origin xyz="0.2 0 0" rpy="0 1.57 0"/>
			<geometry>				
				<cylinder radius=".05" length="0.4" />
			</geometry>
		</collision>

		<inertial>
			<mass value="3" />

			<inertia ixx="4" ixy="0" ixz="0" iyy="4" iyz="0" izz="0" />
		</inertial>
	</link>

	<link name="right_back_leg" >
		<visual>
			<origin xyz="0.2 0 0" rpy="0 1.57 0"/>
			<geometry>				
				<cylinder radius=".05" length="0.4" />
			</geometry>
			<material name="red" />
		</visual>

		<collision>
			<origin xyz="0.2 0 0" rpy="0 1.57 0"/>
			<geometry>				
				<cylinder radius=".05" length="0.4" />
			</geometry>
		</collision>

		<inertial>
			<mass value="3" />

			<inertia ixx="4" ixy="0" ixz="0" iyy="4" iyz="0" izz="0" />
		</inertial>
	</link>

	<link name="left_front_calf" >
		<visual>
			<origin xyz="0.175 0 0" rpy="0 1.57 0"/>
			<geometry>				
				<cylinder radius=".05" length="0.35" />
			</geometry>
			<material name="red" />
		</visual>

		<collision>
			<origin xyz="0.175 0 0" rpy="0 1.57 0"/>
			<geometry>				
				<cylinder radius=".05" length="0.35" />
			</geometry>
		</collision>

		<inertial>
			<mass value="3" />

			<inertia ixx="4" ixy="0" ixz="0" iyy="4" iyz="0" izz="0" />
		</inertial>
	</link>

	<link name="right_front_calf" >
		<visual>
			<origin xyz="0.175 0 0" rpy="0 1.57 0"/>
			<geometry>				
				<cylinder radius=".05" length="0.35" />
			</geometry>
			<material name="red" />
		</visual>

		<collision>
			<origin xyz="0.175 0 0" rpy="0 1.57 0"/>
			<geometry>				
				<cylinder radius=".05" length="0.35" />
			</geometry>
		</collision>

		<inertial>
			<mass value="3" />

			<inertia ixx="4" ixy="0" ixz="0" iyy="4" iyz="0" izz="0" />
		</inertial>
	</link>

	<link name="left_back_calf" >
		<visual>
			<origin xyz="0.175 0 0" rpy="0 1.57 0"/>
			<geometry>				
				<cylinder radius=".05" length="0.35" />
			</geometry>
			<material name="red" />
		</visual>

		<collision>
			<origin xyz="0.175 0 0" rpy="0 1.57 0"/>
			<geometry>				
				<cylinder radius=".05" length="0.35" />
			</geometry>
		</collision>

		<inertial>
			<mass value="3" />

			<inertia ixx="4" ixy="0" ixz="0" iyy="4" iyz="0" izz="0" />
		</inertial>
	</link>

	<link name="right_back_calf" >
		<visual>
			<origin xyz="0.175 0 0" rpy="0 1.57 0"/>
			<geometry>				
				<cylinder radius=".05" length="0.35" />
			</geometry>
			<material name="red" />
		</visual>

		<collision>
			<origin xyz="0.175 0 0" rpy="0 1.57 0"/>
			<geometry>				
				<cylinder radius=".05" length="0.35" />
			</geometry>
		</collision>

		<inertial>
			<mass value="3" />

			<inertia ixx="4" ixy="0" ixz="0" iyy="4" iyz="0" izz="0" />
		</inertial>
	</link>

	<link name="left_front_foot" >
		<visual>
			<origin xyz="0 0 0" rpy="0 0 0"/>
			<geometry>				
				<sphere radius=".05" />
			</geometry>
			<material name="white" />
		</visual>

		<collision>
			<origin xyz="0 0 0" rpy="0 0 0"/>
			<geometry>
				<sphere radius=".05" />
			</geometry>
		</collision>

		<inertial>
			<mass value=".75" />

			<inertia ixx=".003" ixy="0" ixz="0" iyy=".003" iyz="0" izz=".003" />
		</inertial>
	</link>
 <!--
		<gazebo reference="left_front_foot"> 
                <mu1>1</mu1>
                <mu2>1</mu2>
                <fdir1>1 0 0</fdir1>
                <maxContacts>1</maxContacts>
                <minDepth>0.005</minDepth>
                <gravity>true</gravity>
                <collision name="$lowerleg_fixed_joint_lump_$left_front_foot_collision">
                        <geometry>
                                <sphere>
                                        
                                        <radius>0.05</radius>
                                </sphere>
                        </geometry>

                <surface>
                        <friction>
                                <torsional>
                                        <coefficient>10</coefficient>
                                        <use_patch_radius>false</use_patch_radius>
                                       
                                        <surface_radius>0.05</surface_radius>
                                        <patch_radius>0.0158</patch_radius>
                                </torsional>
                        </friction>
                        <contact>
                                <poissons_ratio>0.5</poissons_ratio>
                                <elastic_modulus>1e2</elastic_modulus>
                        </contact>
                </surface>
        </collision>
	<material>Gazebo/Black</material>
        </gazebo>
-->

	<link name="right_front_foot" >
		<visual>
			<origin xyz="0 0 0" rpy="0 0 0"/>
			<geometry>				
				<sphere radius=".05" />
			</geometry>
			<material name="white" />
		</visual>

		<collision>
			<origin xyz="0 0 0" rpy="0 0 0"/>
			<geometry>
				<sphere radius=".05" />
			</geometry>
		</collision>

		<inertial>
			<mass value=".75" />

			<inertia ixx=".003" ixy="0" ixz="0" iyy=".003" iyz="0" izz=".003" />
		</inertial>
	</link>

 <!--
		<gazebo reference="right_front_foot">
                <mu1>1</mu1>
                <mu2>1</mu2>
                <fdir1>1 0 0</fdir1>
                <maxContacts>1</maxContacts>
                <minDepth>0.005</minDepth>
                <gravity>true</gravity>
                <collision name="$lowerleg_fixed_joint_lump_$right_front_foot_collision">
                        <geometry>
                                <sphere>
                                        
                                        <radius>0.05</radius>
                                </sphere>
                        </geometry>

                <surface>
                        <friction>
                                <torsional>
                                        <coefficient>10</coefficient>
                                        <use_patch_radius>false</use_patch_radius>
                                       
                                        <surface_radius>0.05</surface_radius>
                                        <patch_radius>0.0158</patch_radius>
                                </torsional>
                        </friction>
                        <contact>
                                <poissons_ratio>0.5</poissons_ratio>
                                <elastic_modulus>1e2</elastic_modulus>
                        </contact>
                </surface>
        </collision>
	<material>Gazebo/Black</material>
        </gazebo>
-->

	<link name="left_back_foot" >
		<visual>
			<origin xyz="0 0 0" rpy="0 0 0"/>
			<geometry>				
				<sphere radius=".05" />
			</geometry>
			<material name="white" />
		</visual>

		<collision>
			<origin xyz="0 0 0" rpy="0 0 0"/>
			<geometry>
				<sphere radius=".05" />
			</geometry>
		</collision>

		<inertial>
			<mass value=".75" />

			<inertia ixx=".003" ixy="0" ixz="0" iyy=".003" iyz="0" izz=".003" />
		</inertial>
	</link>

  <!--
	<gazebo reference="left_back_foot">
                <mu1>1</mu1>
                <mu2>1</mu2>
                <fdir1>1 0 0</fdir1>
                <maxContacts>1</maxContacts>
                <minDepth>0.005</minDepth>
                <gravity>true</gravity>
                <collision name="$lowerleg_fixed_joint_lump_$left_back_foot_collision">
                        <geometry>
                                <sphere>
                                       
                                        <radius>0.05</radius>
                                </sphere>
                        </geometry>

                <surface>
                        <friction>
                                <torsional>
                                        <coefficient>10</coefficient>
                                        <use_patch_radius>false</use_patch_radius>
                                        
                                        <surface_radius>0.05</surface_radius>
                                        <patch_radius>0.0158</patch_radius>
                                </torsional>
                        </friction>
                        <contact>
                                <poissons_ratio>0.5</poissons_ratio>
                                <elastic_modulus>1e2</elastic_modulus>
                        </contact>
                </surface>
        </collision>
	<material>Gazebo/Black</material>
        </gazebo>
-->

	<link name="right_back_foot" >
		<visual>
			<origin xyz="0 0 0" rpy="0 0 0"/>
			<geometry>				
				<sphere radius=".05" />
			</geometry>
			<material name="white" />
		</visual>

		<collision>
			<origin xyz="0 0 0" rpy="0 0 0"/>
			<geometry>
				<sphere radius=".05" />
			</geometry>
		</collision>

		<inertial>
			<mass value=".75" />

			<inertia ixx=".003" ixy="0" ixz="0" iyy=".003" iyz="0" izz=".003" />
		</inertial>
	</link>

  <!--
        <gazebo reference="right_back_foot">
                <mu1>1</mu1>
                <mu2>1</mu2>
                <fdir1>1 0 0</fdir1>
                <maxContacts>1</maxContacts>
                <minDepth>0.005</minDepth>
                <gravity>true</gravity>
                <collision name="$lowerleg_fixed_joint_lump_$right_back_foot_collision">
                        <geometry>
                                <sphere>
                                        
                                        <radius>0.05</radius>
                                </sphere>
                        </geometry>

                <surface>
                        <friction>
                                <torsional>
                                        <coefficient>10</coefficient>
                                        <use_patch_radius>false</use_patch_radius>
                                        
                                        <surface_radius>0.05</surface_radius>
                                        <patch_radius>0.0158</patch_radius>
                                </torsional>
                        </friction>
                        <contact>
                                <poissons_ratio>0.5</poissons_ratio>
                                <elastic_modulus>1e2</elastic_modulus>
                        </contact>
                </surface>
        </collision>
        <material>Gazebo/Black</material>
        </gazebo>
-->

	<joint name="dummy_joint" type="fixed">
		<parent link="dummy" />
		<child link="base_link" />
	</joint>

	<joint name="left_front_leg_shoulder_hinge" type="revolute">
		<origin xyz="0.5 .2 0" rpy="1.57 0 -1.57"/>
		<parent link="base_link" />
		<child link="left_front_shoulder" />
		<axis xyz="0 0 1" />

		<limit lower="-1.57" upper="1.57" effort="1000" velocity="10" />
	</joint>

	<joint name="right_front_leg_shoulder_hinge" type="revolute">
		<origin xyz="0.5 -.2 0" rpy="1.57 0 1.57"/>
		<parent link="base_link" />
		<child link="right_front_shoulder" />
		<axis xyz="0 0 1" />

		<limit lower="-1.57" upper="1.57" effort="1000" velocity="10" />
	</joint>

	<joint name="left_back_leg_shoulder_hinge" type="revolute">
		<origin xyz="-0.5 .2 0" rpy="1.57 0 -1.57"/>
		<parent link="base_link" />
		<child link="left_back_shoulder" />
		<axis xyz="0 0 1" />

		<limit lower="-1.57" upper="1.57" effort="1000" velocity="10" />
	</joint>

	<joint name="right_back_leg_shoulder_hinge" type="revolute">
		<origin xyz="-0.5 -.2 0" rpy="1.57 0 1.57"/>
		<parent link="base_link" />
		<child link="right_back_shoulder" />
		<axis xyz="0 0 1" />

		<limit lower="-1.57" upper="1.57" effort="1000" velocity="10" />
	</joint>

	<joint name="left_front_leg_shoulder_rotate" type="revolute">
		<origin xyz="-.1 0 0" rpy="1.57 0 -1.57"/>
		<parent link="left_front_shoulder" />
		<child link="left_front_leg" />
		<axis xyz="0 0 1" />

		<limit lower="-1.57" upper="1.57" effort="1000" velocity="10" />
	</joint>

	<joint name="right_front_leg_shoulder_rotate" type="revolute">
		<origin xyz="-.1 0 0" rpy="1.57 0 -1.57"/>
		<parent link="right_front_shoulder" />
		<child link="right_front_leg" />
		<axis xyz="0 0 1" />

		<limit lower="-1.57" upper="1.57" effort="1000" velocity="10" />
	</joint>

	<joint name="left_back_leg_shoulder_rotate" type="revolute">
		<origin xyz="-.1 0 0" rpy="1.57 0 -1.57"/>
		<parent link="left_back_shoulder" />
		<child link="left_back_leg" />
		<axis xyz="0 0 1" />

		<limit lower="-1.57" upper="1.57" effort="1000" velocity="10" />
	</joint>

	<joint name="right_back_leg_shoulder_rotate" type="revolute">
		<origin xyz="-.1 0 0" rpy="1.57 0 -1.57"/>
		<parent link="right_back_shoulder" />
		<child link="right_back_leg" />
		<axis xyz="0 0 1" />

		<limit lower="-1.57" upper="1.57" effort="1000" velocity="10" />
	</joint>

	<joint name="left_front_leg_elbow_hinge" type="revolute">
		<origin xyz="0.4 0 0" rpy="0 0 0" />
		<parent link="left_front_leg" />
		<child link="left_front_calf" />
		<axis xyz="0 0 1" />

		<limit lower="-3.14159" upper="3.14159" effort="1000" velocity="10" />
	</joint>

	<joint name="right_front_leg_elbow_hinge" type="revolute">
		<origin xyz="0.4 0 0" rpy="0 0 0" />
		<parent link="right_front_leg" />
		<child link="right_front_calf" />
		<axis xyz="0 0 1" />

		<limit lower="-3.14159" upper="3.14159" effort="1000" velocity="10" />
	</joint>

	<joint name="left_back_leg_elbow_hinge" type="revolute">
		<origin xyz="0.4 0 0" rpy="0 0 0" />
		<parent link="left_back_leg" />
		<child link="left_back_calf" />
		<axis xyz="0 0 1" />

		<limit lower="-3.14159" upper="3.14159" effort="1000" velocity="10" />
	</joint>

	<joint name="right_back_leg_elbow_hinge" type="revolute">
		<origin xyz="0.4 0 0" rpy="0 0 0" />
		<parent link="right_back_leg" />
		<child link="right_back_calf" />
		<axis xyz="0 0 1" />

		<limit lower="-3.14159" upper="3.14159" effort="1000" velocity="10" />
	</joint>

	<joint name="left_front_foot_hinge" type="fixed">
		<origin xyz="0.35 0 0" rpy="0 0 0" />
		<parent link="left_front_calf" />
		<child link="left_front_foot" />
	</joint>

	<joint name="right_front_foot_hinge" type="fixed">
		<origin xyz="0.35 0 0" rpy="0 0 0" />
		<parent link="right_front_calf" />
		<child link="right_front_foot" />
	</joint>

	<joint name="left_back_foot_hinge" type="fixed">
		<origin xyz="0.35 0 0" rpy="0 0 0" />
		<parent link="left_back_calf" />
		<child link="left_back_foot" />
	</joint>

	<joint name="right_back_foot_hinge" type="fixed">
		<origin xyz="0.35 0 0" rpy="0 0 0" />
		<parent link="right_back_calf" />
		<child link="right_back_foot" />
	</joint>


	<transmission name="left_front_leg_shoulder_rotate_transmission">
		<type>transmission_interface/SimpleTransmission</type>
		<joint name="left_front_leg_shoulder_rotate">
			<hardwareInterface>hardware_interface/EffortJointInterface</hardwareInterface>
		</joint>
		<actuator name="left_front_leg_shoulder_rotate_motor">
			<mechanicalReduction>1</mechanicalReduction>
		</actuator>
	</transmission>

	<transmission name="right_front_leg_shoulder_rotate_transmission">
		<type>transmission_interface/SimpleTransmission</type>
		<joint name="right_front_leg_shoulder_rotate">
			<hardwareInterface>hardware_interface/EffortJointInterface</hardwareInterface>
		</joint>
		<actuator name="right_front_leg_shoulder_rotate_motor">
			<mechanicalReduction>1</mechanicalReduction>
		</actuator>
	</transmission>

	<transmission name="left_back_leg_shoulder_rotate_transmission">
		<type>transmission_interface/SimpleTransmission</type>
		<joint name="left_back_leg_shoulder_rotate">
			<hardwareInterface>hardware_interface/EffortJointInterface</hardwareInterface>
		</joint>
		<actuator name="left_back_leg_shoulder_rotate_motor">
			<mechanicalReduction>1</mechanicalReduction>
		</actuator>
	</transmission>

	<transmission name="right_back_leg_shoulder_rotate_transmission">
		<type>transmission_interface/SimpleTransmission</type>
		<joint name="right_back_leg_shoulder_rotate">
			<hardwareInterface>hardware_interface/EffortJointInterface</hardwareInterface>
		</joint>
		<actuator name="right_back_leg_shoulder_rotate_motor">
			<mechanicalReduction>1</mechanicalReduction>
		</actuator>
	</transmission>

	<transmission name="left_front_leg_shoulder_hinge_transmission">
		<type>transmission_interface/SimpleTransmission</type>
		<joint name="left_front_leg_shoulder_hinge">
			<hardwareInterface>hardware_interface/EffortJointInterface</hardwareInterface>
		</joint>
		<actuator name="left_front_leg_shoulder_hinge_motor">
			<mechanicalReduction>1</mechanicalReduction>
		</actuator>
	</transmission>

	<transmission name="right_front_leg_shoulder_hinge_transmission">
		<type>transmission_interface/SimpleTransmission</type>
		<joint name="right_front_leg_shoulder_hinge">
			<hardwareInterface>hardware_interface/EffortJointInterface</hardwareInterface>
		</joint>
		<actuator name="right_front_leg_shoulder_hinge_motor">
			<mechanicalReduction>1</mechanicalReduction>
		</actuator>
	</transmission>

	<transmission name="left_back_leg_shoulder_hinge_transmission">
		<type>transmission_interface/SimpleTransmission</type>
		<joint name="left_back_leg_shoulder_hinge">
			<hardwareInterface>hardware_interface/EffortJointInterface</hardwareInterface>
		</joint>
		<actuator name="left_back_leg_shoulder_hinge_motor">
			<mechanicalReduction>1</mechanicalReduction>
		</actuator>
	</transmission>

	<transmission name="right_back_leg_shoulder_hinge_transmission">
		<type>transmission_interface/SimpleTransmission</type>
		<joint name="right_back_leg_shoulder_hinge">
			<hardwareInterface>hardware_interface/EffortJointInterface</hardwareInterface>
		</joint>
		<actuator name="right_back_leg_shoulder_hinge_motor">
			<mechanicalReduction>1</mechanicalReduction>
		</actuator>
	</transmission>

	<transmission name="left_front_leg_elbow_hinge_transmission">
		<type>transmission_interface/SimpleTransmission</type>
		<joint name="left_front_leg_elbow_hinge">
			<hardwareInterface>hardware_interface/EffortJointInterface</hardwareInterface>
		</joint>
		<actuator name="left_front_leg_elbow_hinge_motor">
			<mechanicalReduction>1</mechanicalReduction>
		</actuator>
	</transmission>

	<transmission name="right_front_leg_elbow_hinge_transmission">
		<type>transmission_interface/SimpleTransmission</type>
		<joint name="right_front_leg_elbow_hinge">
			<hardwareInterface>hardware_interface/EffortJointInterface</hardwareInterface>
		</joint>
		<actuator name="right_front_leg_elbow_hinge_motor">
			<mechanicalReduction>1</mechanicalReduction>
		</actuator>
	</transmission>

	<transmission name="left_back_leg_elbow_hinge_transmission">
		<type>transmission_interface/SimpleTransmission</type>
		<joint name="left_back_leg_elbow_hinge">
			<hardwareInterface>hardware_interface/EffortJointInterface</hardwareInterface>
		</joint>
		<actuator name="left_back_leg_elbow_hinge_motor">
			<mechanicalReduction>1</mechanicalReduction>
		</actuator>
	</transmission>

	<transmission name="right_back_leg_elbow_hinge_transmission">
		<type>transmission_interface/SimpleTransmission</type>
		<joint name="right_back_leg_elbow_hinge">
			<hardwareInterface>hardware_interface/EffortJointInterface</hardwareInterface>
		</joint>
		<actuator name="right_back_leg_elbow_hinge_motor">
			<mechanicalReduction>1</mechanicalReduction>
		</actuator>
	</transmission>

	<gazebo>
		<plugin name="gazebo_ros_control" filename="libgazebo_ros_control.so">
			<!-- <robotSimType>gazebo_ros_control/DefaultRobotHWSim</robotSimType> -->
			<robotNamespace>/quadrupedal_test</robotNamespace>
		</plugin>

		<plugin name="p3d_controller" filename="libgazebo_ros_p3d.so">
			<alwaysOn>true</alwaysOn>
			<updateRate>1000</updateRate>
			<bodyName>base_link</bodyName>
			<topicName>p3d_robot</topicName>
		</plugin>
	</gazebo>

</robot>
